Workbook

Sheet Cover Page
D20: Prepared by: Hilal S. Berhe
D21: Project Type: Financial Planning & Analysis / Budget vs. Actual / Reforecasting
D22: Company: Walmart Inc.
D23: Data Source: Public company filings, investor relations materials, and earnings releases
D24: Currency: USD in millions, except per-share data if used
D25: Model Period: FY2022–FY2026E
D26: Purpose: To analyze Walmart’s quarterly financial performance

Sheet Historicals 
A1: Income Statement Historical Data
A3: USD $ millions, except per-share data | B3: FY2023A | C3: FY2024A | D3: FY2025A | E3: FY2026A
A4: Revenue
A5: Net Sales | B5: 605881 | C5: 642637 | D5: 674538 | E5: 706413
A6: Membership & Other Income | B6: 5408 | C6: 5488 | D6: 6447 | E6: 6750
A7: Total Revenue | B7: =SUM(B5,B6) -> 611289 | C7: =SUM(C5,C6) -> 648125 | D7: =SUM(D5,D6) -> 680985 | E7: =SUM(E5,E6) -> 713163
A8: Revenue Growth % | B8: - | C8: =C7/B7-1 -> 0.06025955 | D8: =D7/C7-1 -> 0.050700096 | E8: =E7/D7-1 -> 0.047252142
A9: Cost & Gross Profit
A10: Cost of Sales / COGS | B10: 463721 | C10: 490142 | D10: 511753 | E10: 535395
A11: Gross Profit | B11: =B5-B10 -> 142160 | C11: =C5-C10 -> 152495 | D11: =D5-D10 -> 162785 | E11: =E5-E10 -> 171018
A12: Gross Margin % | B12: =B11/B5 -> 0.23463353 | C12: =C11/C5 -> 0.23729571 | D12: =D11/D5 -> 0.24132814 | E12: =E11/E5 -> 0.24209351
A13: Operating Expenses
A14: SG&A Expense | B14: 127140 | C14: 130971 | D14: 139884 | E14: 147943
A15: SG&A % of Net Sales | B15: =B14/B5 -> 0.20984319 | C15: =C14/C5 -> 0.20380246 | D15: =D14/D5 -> 0.20737749 | E15: =E14/E5 -> 0.20942848
A16: Operating Income | B16: 20428 | C16: 27012 | D16: 29348 | E16: 29825
A17: Operating Margin % | B17: =B16/B7 -> 0.033417909 | C17: =C16/C7 -> 0.041677146 | D17: =D16/D7 -> 0.043096397 | E17: =E16/E7 -> 0.041820734
A18: Interest / Other
A19: Interest Expense — Debt | B19: 1787 | C19: 2259 | D19: 2249 | E19: 2318
A20: Interest Expense — Finance Lease | B20: 341 | C20: 424 | D20: 479 | E20: 481
A21: Interest Income | B21: -254 | C21: -546 | D21: -483 | E21: -368
A22: Interest, Net | B22: 1874 | C22: 2137 | D22: 2245 | E22: 2431
A23: Other Gains / Losses | B23: 1538 | C23: 3027 | D23: 794 | E23: -2075
A24: Income Before Taxes | B24: 17016 | C24: 21848 | D24: 26309 | E24: 29469
A25: Taxes & Net Income
A26: Income Tax Expense | B26: 5724 | C26: 5578 | D26: 6152 | E26: 7199
A27: Effective Tax Rate % | B27: =B26/B24 -> 0.33638928 | C27: =C26/C24 -> 0.25530941 | D27: =D26/D24 -> 0.23383633 | E27: =E26/E24 -> 0.24429061
A28: Consolidated Net Income | B28: 11292 | C28: 16270 | D28: 20157 | E28: 22270
A29: Noncontrolling Interest Adjustment | B29: 388 | C29: -759 | D29: -721 | E29: -377
A30: Net Income Attributable to Walmart | B30: 11680 | C30: 15511 | D30: 19436 | E30: 21893
A31: Net Margin % | B31: =B30/B7 -> 0.019107165 | C31: =C30/C7 -> 0.023932112 | D31: =D30/D7 -> 0.02854101 | E31: =E30/E7 -> 0.030698452
A32: Diluted EPS | B32: 1.42 | C32: 1.91 | D32: 2.41 | E32: 2.73
A33: Diluted Shares Outstanding | B33: 8202 | C33: 8108 | D33: 8081 | E33: 8022
A40: Cash Flow Historical Data
A42: USD $ millions, except per-share data | B42: FY2023A | C42: FY2024A | D42: FY2025A | E42: FY2026A
A43: Cash Flow & Free Cash Flow
A44: Depreciation & Amortization | B44: 10945 | C44: 11853 | D44: 12973 | E44: 14203
A45: Cash Flow from Operations | B45: 28841 | C45: 35726 | D45: 36443 | E45: 41565
A46: CapEx / Payments for Property & Equipment | B46: -16857 | C46: -20606 | D46: -23783 | E46: -26642
A47: Free Cash Flow | B47: =B45+B46 -> 11984 | C47: =C45+C46 -> 15120 | D47: =D45+D46 -> 12660 | E47: =E45+E46 -> 14923
A48: CapEx % of Revenue | B48: =ABS(B46)/B7 -> 0.027576155 | C48: =ABS(C46)/C7 -> 0.03179325 | D48: =ABS(D46)/D7 -> 0.034924411 | E48: =ABS(E46)/E7 -> 0.037357519
...

Sheet Assumptions
A1: Assumptions/ Budget Drivers
A3: USD $ millions, except per-share data | B3: FY2023A | C3: FY2024A | D3: FY2025A | E3: FY2026A | F3: Historical Average | G3: FY2027 Budget Assumption
A4: Driver
A5: Revenue Growth % | B5: ='Historicals '!B8 -> - | C5: ='Historicals '!C8 -> 0.06025955 | D5: ='Historicals '!D8 -> 0.050700096 | E5: ='Historicals '!E8 -> 0.047252142 | F5: =AVERAGE(C5:E5) -> 0.052737263 | G5: =F5 -> 0.052737263
A6: Gross Margin % | B6: ='Historicals '!B12 -> 0.23463353 | C6: ='Historicals '!C12 -> 0.23729571 | D6: ='Historicals '!D12 -> 0.24132814 | E6: ='Historicals '!E12 -> 0.24209351 | F6: =AVERAGE(B6:E6) -> 0.23883772 | G6: =F6 -> 0.23883772
A7: SG&A % of Net Sales | B7: ='Historicals '!B15 -> 0.20984319 | C7: ='Historicals '!C15 -> 0.20380246 | D7: ='Historicals '!D15 -> 0.20737749 | E7: ='Historicals '!E15 -> 0.20942848 | F7: =AVERAGE(B7:E7) -> 0.2076129 | G7: =F7 -> 0.2076129
A8: Operating Margin % | B8: ='Historicals '!B17 -> 0.033417909 | C8: ='Historicals '!C17 -> 0.041677146 | D8: ='Historicals '!D17 -> 0.043096397 | E8: ='Historicals '!E17 -> 0.041820734 | F8: =AVERAGE(B8:E8) -> 0.040003046 | G8: =F8 -> 0.040003046
A9: Effective Tax Rate % | B9: ='Historicals '!B27 -> 0.33638928 | C9: ='Historicals '!C27 -> 0.25530941 | D9: ='Historicals '!D27 -> 0.23383633 | E9: ='Historicals '!E27 -> 0.24429061 | F9: =AVERAGE(B9:E9) -> 0.26745641 | G9: =F9 -> 0.26745641
A10: CapEx % of Revenue | B10: ='Historicals '!B48 -> 0.027576155 | C10: ='Historicals '!C48 -> 0.03179325 | D10: ='Historicals '!D48 -> 0.034924411 | E10: ='Historicals '!E48 -> 0.037357519 | F10: =AVERAGE(B10:E10) -> 0.032912833 | G10: =F10 -> 0.032912833
A11: FCF Margin % | B11: ='Historicals '!B49 -> 0.019604475 | C11: ='Historicals '!C49 -> 0.023328833 | D11: ='Historicals '!D49 -> 0.018590718 | E11: ='Historicals '!E49 -> 0.02092509 | F11: =AVERAGE(B11:E11) -> 0.020612279 | G11: =F11 -> 0.020612279

Sheet Budget
A1: FY2027 Budget
A3: USD $ millions, except per-share data | B3: FY2026A | C3: FY2027 Budget
A4: Revenue
A5: Net Sales | B5: 706413 | C5: =B5*(1+C8) -> 743852.89
A6: Membership & Other Income | B6: 6750 | C6: =B6*(1+C8) -> 7107.75
A7: Total Revenue | B7: 713163 | C7: =SUM(C5,C6) -> 750960.64
A8: Revenue Growth % | B8: 0.047 | C8: 0.053
A9: Cost & Gross Profit
A10: Cost of Sales / COGS | B10: 535395
A11: Gross Profit | B11: 171018 | C11: =C5*C12 -> 177780.84
A12: Gross Margin % | B12: 0.242 | C12: 0.239
A13: Operating Expenses
A14: SG&A Expense | B14: 147943 | C14: =C5*C15 -> 154721.4
A15: SG&A % of Net Sales | B15: 0.209 | C15: 0.208
A16: Operating Income | B16: 29825 | C16: =C11+C6-C14 -> 30167.19
A17: Operating Margin % | B17: 0.042 | C17: 0.04
A18: Taxes & Net Income
A19: Income Before Taxes | B19: 29469 | C19: =C16+(B19-B16) -> 29811.19
A20: Income Tax Expense | B20: 7199 | C20: =C19*C21 -> 7959.5876
A21: Effective Tax Rate % | B21: 0.244 | C21: 0.267
A22: Net Income Attributable to Walmart | B22: 21893 | C22: =C19-C20 -> 21851.602
A23: Net Margin % | B23: 0.031 | C23: =C22/C7 -> 0.029098199
A24: Cash Flow
A25: CapEx | B25: -26642 | C25: =C7*C26*-1 -> -24781.701
A26: CapEx % of Revenue | B26: 0.037 | C26: 0.033
A27: Free Cash Flow | B27: 14923 | C27: =C28*C7 -> 15770.173
A28: FCF Margin % | B28: 0.021 | C28: 0.021

Sheet Budget Variance Analysis
A2: FY2027 Budget vs FY2026A
A4: USD $ millions, except per-share data | B4: FY2026A | C4: FY2027 Budget | D4: $Variance | E4: % / bps Variance
A5: Revenue
A6: Net Sales | B6: 706413 | C6: =B6*(1+C9) -> 743852.89 | D6: =C6-B6 -> 37439.889 | E6: =D6/B6 -> 0.053
A7: Membership & Other Income | B7: 6750 | C7: =B7*(1+C9) -> 7107.75 | D7: =C7-B7 -> 357.75 | E7: =D7/B7 -> 0.053
A8: Total Revenue | B8: 713163 | C8: =SUM(C6,C7) -> 750960.64 | D8: =C8-B8 -> 37797.639 | E8: =D8/B8 -> 0.053
A9: Revenue Growth % | B9: 0.047 | C9: 0.053 | E9: =(C9-B9)*10000 -> 60
A10: Cost & Gross Profit
A11: Cost of Sales / COGS | B11: 535395 | C11: 566072 | D11: =C11-B11 -> 30677 | E11: =D11/B11 -> 0.057297883
A12: Gross Profit | B12: 171018 | C12: =C6*C13 -> 177780.84 | D12: =C12-B12 -> 6762.8405 | E12: =D12/B12 -> 0.039544612
A13: Gross Margin % | B13: 0.242 | C13: 0.239 | E13: =(C13-B13) * 10000 -> -30
A14: Operating Expenses
A15: SG&A Expense | B15: 147943 | C15: =C6*C16 -> 154721.4 | D15: =C15-B15 -> 6778.4009 | E15: =D15/B15 -> 0.045817652
A16: SG&A % of Net Sales | B16: 0.209 | C16: 0.208 | E16: =(C16-B16)*10000 -> -10
A17: Operating Income | B17: 29825 | C17: =C12+C7-C15 -> 30167.19 | D17: =C17-B17 -> 342.18956 | E17: =D17/B17 -> 0.011473246
A18: Operating Margin % | B18: 0.042 | C18: 0.04 | E18: =(C18-B18)*10000 -> -20
A19: Taxes & Net Income
A20: Income Before Taxes | B20: 29469 | C20: =C17+(B20-B17) -> 29811.19 | D20: =C20-B20 -> 342.18956 | E20: =D20/B20 -> 0.011611848
A21: Income Tax Expense | B21: 7199 | C21: =C20*C22 -> 7959.5876 | D21: =C21-B21 -> 760.58761 | E21: =D21/B21 -> 0.10565184
A22: Effective Tax Rate % | B22: 0.244 | C22: 0.267 | E22: =(C22-B22)*10000 -> 230
A23: Net Income Attributable to Walmart | B23: 21893 | C23: =C20-C21 -> 21851.602 | D23: =C23-B23 -> -41.398053 | E23: =D23/B23 -> -0.0018909265
A24: Net Margin % | B24: 0.031 | C24: =C23/C8 -> 0.029098199 | E24: =(C24-B24)*10000 -> -19.018012
A25: Cash Flow
A26: CapEx | B26: -26642 | C26: =C8*C27*-1 -> -24781.701 | D26: =C26-B26 -> 1860.2989 | E26: =D26/B26 -> -0.069825798
A27: CapEx % of Revenue | B27: 0.037 | C27: 0.033 | E27: =(C27-B27)*10000 -> -40
A28: Free Cash Flow | B28: 14923 | C28: =C29*C8 -> 15770.173 | D28: =C28-B28 -> 847.17342 | E28: =D28/B28 -> 0.056769645
A29: FCF Margin % | B29: 0.021 | C29: 0.021 | E29: =(C29-B29)*10000 -> 0

Sheet Reforecast
A1: FY2027 Reforecast
A3: USD $ millions, except per-share data | B3: FY2026A | C3: FY2027 Budget | D3: Q1 FY2027 Actual | E3: Q2 FY2027 Forecast | F3: Q3 FY2027 Forecast | G3: Q4 FY2027 Forecast | H3: FY2027 Reforecast | I3: Variance vs Budget
A4: Revenue
A5: Net Sales | B5: 706413 | C5: 743853 | D5: 175684 | E5: =D5*(1+E8) -> 179197.68 | F5: =E5*(1+F8) -> 181885.65 | G5: =F5*(1+G8) -> 186432.79 | H5: =SUM(D5,E5,F5,G5) -> 723200.11 | I5: =H5-C5 -> -20652.888
A6: Membership & Other Income | B6: 6750 | C6: 7108 | D6: 2067 | E6: =D6*(1+E8) -> 2108.34 | F6: =E6*(1+F8) -> 2139.9651 | G6: =F6*(1+G8) -> 2193.4642 | H6: =SUM(D6,E6,F6,G6) -> 8508.7693 | I6: =H6-C6 -> 1400.7693
A7: Total Revenue | B7: 713163 | C7: 750961 | D7: 177751 | E7: =(E6+E5) -> 181306.02 | F7: =(F6+F5) -> 184025.61 | G7: =(G6+G5) -> 188626.25 | H7: =SUM(D7,E7,F7,G7) -> 731708.88 | I7: =H7-C7 -> -19252.119
A8: Revenue Growth % | B8: 0.047 | C8: 0.053 | D8: 0.071 | E8: 0.02 | F8: 0.015 | G8: 0.025 | H8: =H5/B5-1 -> 0.023763877 | I8: =(H8-C8)*10000 -> -292.36123
A9: Cost & Gross Profit
A10: Cost of Sales / COGS | B10: 535395 | C10: 566072 | D10: 133058 | E10: =E5-E11 -> 136190.24 | F10: =F5-F11 -> 138414.98 | G10: =G5-G11 -> 141875.35 | H10: =SUM(D10,E10,F10,G10) -> 549538.56 | I10: =H10-C10 -> -16533.437
A11: Gross Profit | B11: 171018 | C11: 177781 | D11: 42626 | E11: =E5*E12 -> 43007.443 | F11: =F5*F12 -> 43470.669 | G11: =G5*G12 -> 44557.436 | H11: =SUM(D11,E11,F11,G11) -> 173661.55 | I11: =H11-C11 -> -4119.4517
A12: Gross Margin % | B12: 0.242 | C12: 0.239 | D12: 0.243 | E12: 0.24 | F12: 0.239 | G12: 0.239 | H12: =H11/H5 -> 0.24012932 | I12: =(H12-C12)*10000 -> 11.293163
A13: Operating Expenses
A14: SG&A Expense | B14: 147943 | C14: 154721 | D14: 37200 | E14: =E5*E15 -> 37452.315 | F14: =F5*F15 -> 37832.214 | G14: =G5*G15 -> 38591.587 | H14: =SUM(D14,E14,F14,G14) -> 151076.12 | I14: =H14-C14 -> -3644.8839
A15: SG&A % of Net Sales | B15: 0.209 | C15: 0.208 | D15: 0.212 | E15: 0.209 | F15: 0.208 | G15: 0.207 | H15: =H14/H5 -> 0.20889946 | I15: =(H15-C15)*10000 -> 8.9946459
A16: Operating Income | B16: 29825 | C16: 30167 | D16: 7493 | E16: =E11+E6-E14 -> 7663.4681 | F16: =F11+F6-F14 -> 7778.4201 | G16: =G11+G6-G14 -> 8159.3134 | H16: =SUM(D16,E16,F16,G16) -> 31094.202 | I16: =H16-C16 -> 927.20157
A17: Operating Margin % | B17: 0.042 | C17: 0.04 | D17: 0.043 | E17: =E16/E7 -> 0.042268139 | F17: =F16/F7 -> 0.042268139 | G17: =G16/G7 -> 0.043256511 | H17: =H16/H7 -> 0.042495318 | I17: =(H17-C17)*10000 -> 24.95318
A18: Taxes & Net Income
A19: Income Before Taxes | B19: 29469 | C19: 29811 | D19: 7148 | E19: =E16-345 -> 7318.4681 | F19: =F16-345 -> 7433.4201 | G19: =G16-345 -> 7814.3134 | H19: =SUM(D19,E19,F19,G19) -> 29714.202 | I19: =H19-C19 -> -96.798429
A20: Income Tax Expense | B20: 7199 | C20: 7960 | D20: 1658 | E20: =E19*(E21) -> 1866.2094 | F20: =F19*(F21) -> 1932.6892 | G20: =G19*(G21) -> 2070.793 | H20: =SUM(D20,E20,F20,G20) -> 7527.6916 | I20: =H20-C20 -> -432.30836
A21: Effective Tax Rate % | B21: 0.244 | C21: 0.267 | D21: 0.232 | E21: 0.255 | F21: 0.26 | G21: 0.265 | H21: =H20/H19 -> 0.25333649 | I21: =(H21-C21)*10000 -> -136.63506
A22: Net Income Attributable to Walmart | B22: 21893 | C22: 21852 | D22: 5330 | E22: =E19-E20 -> 5452.2587 | F22: =F19-F20 -> 5500.7309 | G22: =G19-G20 -> 5743.5203 | H22: =SUM(D22,E22,F22,G22) -> 22026.51 | I22: =H22-C22 -> 174.50994
A23: Net Margin % | B23: 0.031 | C23: 0.0291 | D23: 0.03 | E23: =E22/E7 -> 0.030072133 | F23: =F22/F7 -> 0.029891116 | G23: =G22/G7 -> 0.03044921 | H23: =H22/H7 -> 0.030102833 | I23: =(H23-C23)*10000 -> 10.028326
A24: Cash Flow
A25: CapEx | B25: -26642 | C25: -24782 | D25: -6684 | E25: =E5*3.3%*-1 -> -5913.5234 | F25: =F5*3.3%*-1 -> -6002.2263 | G25: =G5*3.3%*-1 -> -6152.2819 | H25: =SUM(D25,E25,F25,G25) -> -24752.032 | I25: =H25-C25 -> 29.96832
A26: Free Cash Flow | B26: 14923 | C26: 15770 | D26: -1946 | E26: =E7*E27 -> 2719.5903 | F26: =F7*F27 -> 3680.5122 | G26: =G7*G27 -> 4715.6563 | H26: =SUM(D26,E26,F26,G26) -> 9169.7588 | I26: =H26-C26 -> -6600.2412
A27: FCF Margin % | B27: 0.021 | C27: 0.021 | D27: -0.0109 | E27: 0.015 | F27: 0.02 | G27: 0.025 | H27: =H26/H7 -> 0.012531977 | I27: =(H27-C27)*10000 -> -84.680231

Sheet KPI Dashboard
A1: USD $ millions, except per-share data
A5: Table 1 - KPI Summary
A7: KPI | B7: FY2027 Budget | C7: FY2027 Reforecast | D7: Variance vs Budget | E7: Status
A8: Total Revenue | B8: 750961 | C8: 731709 | D8: -19252 | E8: Unfavorable
A9: Net Sales | B9: 743853 | C9: 723200 | D9: -20653 | E9: Unfavorable
A10: Operating Income | B10: 30167 | C10: 31094 | D10: 927 | E10: Favorable
A11: Net Income | B11: 21852 | C11: 22027 | D11: 175 | E11: Favorable
A12: Free Cash Flow | B12: 15770 | C12: 9170 | D12: -6600 | E12: Unfavorable
A13: Gross Margin % | B13: 0.239 | C13: 0.2401 | D13: 11 bps | E13: Favorable
A14: SG&A % of Net Sales | B14: 0.208 | C14: 0.2089 | D14: 9 bps | E14: Unfavorable
A15: Operating Margin % | B15: 0.04 | C15: 0.0425 | D15: 25 bps | E15: Favorable
A16: Effective Tax Rate % | B16: 0.267 | C16: 0.2533 | D16: -137 bps | E16: Favorable
A17: Net Margin % | B17: 0.0291 | C17: 0.0301 | D17: 10 bps | E17: Favorable
A18: FCF Margin % | B18: 0.021 | C18: 0.0125 | D18: -85 bps | E18: Unfavorable
A22: Table 2 - Budget vs Reforecast Chart Data
A26: Metric | B26: FY2027 Budget | C26: FY2027 Reforecast
A27: Total Revenue | B27: 750961 | C27: 731709
A28: Operating Income | B28: 30167 | C28: 31094
A29: Net Income | B29: 21852 | C29: 22027
A30: Free Cash Flow | B30: 15770 | C30: 9170
A35: Table 3 - Margin Comparison Chart Data
A39: Metric | B39: FY2027 Budget | C39: FY2027 Reforecast | D39: Variance bps
A40: Gross Margin % | B40: 0.239 | C40: 0.2401 | D40: 11
A41: SG&A % of Net Sales | B41: 0.208 | C41: 0.2089 | D41: 9
A42: Operating Margin % | B42: 0.04 | C42: 0.0425 | D42: 25
A43: Net Margin % | B43: 0.0291 | C43: 0.0301 | D43: 10
A44: FCF Margin % | B44: 0.021 | C44: 0.0125 | D44: -85
A49: Table 4 - Variance Drivers
A53: Driver | B53: Variance | C53: Impact | D53: Commentary
A54: Net Sales | B54: -20653 | C54: Unfavorable | D54: Reforecast sales are below budget, reducing total revenue.
A55: Membership & Other Income | B55: 1401 | C55: Favorable | D55: Membership and other income is above budget.
A56: Gross Margin | B56: 11 bps | C56: Favorable | D56: Reforecast gross margin is slightly stronger than budget.
A57: SG&A % of Net Sales | B57: 9 bps | C57: Unfavorable | D57: SG&A is higher as a percentage of sales versus budget.
A58: Operating Income | B58: 927 | C58: Favorable | D58: Operating income is above budget despite lower revenue.
A59: Effective Tax Rate | B59: -137 bps | C59: Favorable | D59: Lower tax rate supports net income.
A60: Free Cash Flow | B60: -6600 | C60: Unfavorable | D60: FCF is below budget due to weak Q1 cash flow performance.

Sheet Power BI KPI
A1: Sort Order | B1: KPI | C1: Category | D1: Unit | E1: FY2027 Budget | F1: FY2027 Reforecast | G1: Variance vs Budget | H1: Variance bps | I1: Status
A2: 1 | B2: Total Revenue | C2: Revenue | D2: $ Millions | E2: 750961 | F2: 731709 | G2: -19252 | I2: Unfavorable
A3: 2 | B3: Net Sales | C3: Revenue | D3: $ Millions | E3: 743853 | F3: 723200 | G3: -20653 | I3: Unfavorable
A4: 3 | B4: Gross Profit | C4: Profitability | D4: $ Millions | E4: 177781 | F4: 173662 | G4: -4119 | I4: Unfavorable
A5: 4 | B5: Operating Income | C5: Profitability | D5: $ Millions | E5: 30167 | F5: 31094 | G5: 927 | I5: Favorable
A6: 5 | B6: Net Income | C6: Profitability | D6: $ Millions | E6: 21852 | F6: 22027 | G6: 175 | I6: Favorable
A7: 6 | B7: Free Cash Flow | C7: Cash Flow | D7: $ Millions | E7: 15770 | F7: 9170 | G7: -6600 | I7: Unfavorable
A8: 7 | B8: Gross Margin % | C8: Margin | D8: % | E8: 0.239 | F8: 0.2401 | G8: 0.0011 | H8: 11 | I8: Favorable
A9: 8 | B9: SG&A % of Net Sales | C9: Margin | D9: % | E9: 0.208 | F9: 0.2089 | G9: 0.0009 | H9: 9 | I9: Unfavorable
A10: 9 | B10: Operating Margin % | C10: Margin | D10: % | E10: 0.04 | F10: 0.0425 | G10: 0.0025 | H10: 25 | I10: Favorable
A11: 10 | B11: Net Margin % | C11: Margin | D11: % | E11: 0.0291 | F11: 0.0301 | G11: 0.001 | H11: 10 | I11: Favorable
A12: 11 | B12: FCF Margin % | C12: Margin | D12: % | E12: 0.021 | F12: 0.0125 | G12: -0.0085 | H12: -85 | I12: Unfavorable
A13: 12 | B13: Effective Tax Rate % | C13: Tax | D13: % | E13: 0.267 | F13: 0.2533 | G13: -0.0137 | H13: -137 | I13: Favorable
